<?xml version="1.0" ?>
<!-- =================================================================================== -->
<!-- |    This document was autogenerated by xacro from arm.urdf.xacro                 | -->
<!-- |    EDITING THIS FILE BY HAND IS NOT RECOMMENDED                                 | -->
<!-- =================================================================================== -->
<robot name="arm">
  <link name="world"/>
  <link name="flange"/>
  <joint name="fix_flange" type="fixed">
    <parent link="world"/>
    <child link="flange"/>
  </joint>

    <joint name="fix_colision" type="fixed">
        <parent link="world" />
        <child link="kalman_box" />        
    </joint>

    <link name="kalman_box">
        <visual>
            <geometry>
                <!-- <mesh filename="package://kalman_arm_moveit_config/meshes/gripper/gripper_bottom.stl" scale="0.001 0.001 0.001"/> -->
                <box size="1.0 1.0 0.1"/>
            </geometry>
        <origin rpy="0 0 0" xyz="-0.04 -0.04 -0.12"/>
        <material name="white"/>1
        </visual>
        <collision>
            <geometry>
                <box size="1.0 1.0 0.1"/>

            </geometry>
        <origin rpy="0 0 0" xyz="-0.04 -0.04 -0.12"/>
        </collision>
    </link>

    
  <link name="arm_link">
    <visual>
      <geometry>
        <cylinder length="0" radius="0.089"/>
      </geometry>
      <origin rpy="0 0 0" xyz="0 0 0.0"/>
    </visual>
    <collision>
      <geometry>
        <cylinder length="0" radius="0.089"/>
      </geometry>
      <origin rpy="0 0 0" xyz="0 0 0.0"/>
    </collision>
    <inertial>
      <mass value="0.1"/>
      <inertia ixx="0.03" ixy="0.0" ixz="0.0" iyy="0.03" iyz="0.0" izz="0.03"/>
    </inertial>
  </link>
  <link name="link1">
    <visual>
      <geometry>
        <box size="0.1275 0.089 0.089"/>
      </geometry>
      <origin rpy="0 0 0" xyz="0.0 0 0"/>
      <material name="white"/>
    </visual>
    <collision>
      <geometry>
        <box size="0.1275 0.089 0.089"/>
      </geometry>
      <origin rpy="0 0 0" xyz="0.0 0 0"/>
    </collision>
    <inertial>
      <mass value="0.1"/>
      <inertia ixx="0.03" ixy="0.0" ixz="0.0" iyy="0.03" iyz="0.0" izz="0.03"/>
    </inertial>
  </link>
  <joint name="joint_1" type="revolute">
    <axis xyz="0 0 1"/>
    <limit effort="1000.0" lower="-6.2815926" upper="6.2815926" velocity="0.5"/>
    <parent link="arm_link"/>
    <child link="link1"/>
    <origin rpy="0 0 1.570796" xyz="0 0 0.172"/>
  </joint>
  <link name="link2">
    <visual>
      <geometry>
        <cylinder length="0.41" radius="0.0125"/>
      </geometry>
      <origin rpy="0 0 0" xyz="0.076250 0 0.205"/>
      <material name="white"/>
    </visual>
    <collision>
      <geometry>
        <cylinder length="0.41" radius="0.0125"/>
      </geometry>
      <origin rpy="0 0 0" xyz="0.076250 0 0.205"/>
    </collision>
    <inertial>
      <mass value="0.1"/>
      <inertia ixx="0.03" ixy="0.0" ixz="0.0" iyy="0.03" iyz="0.0" izz="0.03"/>
    </inertial>
  </link>
  <joint name="joint_2" type="revolute">
    <axis xyz="1 0 0"/>
    <limit effort="1000.0" lower="-3.1415926" upper="3.1415926" velocity="0.5"/>
    <parent link="link1"/>
    <child link="link2"/>
    <origin xyz="0 0 0"/>
  </joint>
  <link name="link3">
    <visual>
      <geometry>
        <box size="0.115 0.089 0.089"/>
      </geometry>
      <origin rpy="0 0 0" xyz="0.07 0 0"/>
      <material name="white"/>
    </visual>
    <collision>
      <geometry>
        <box size="0.115 0.089 0.089"/>
      </geometry>
      <origin rpy="0 0 0" xyz="0.07 0 0"/>
    </collision>
    <inertial>
      <mass value="0.1"/>
      <inertia ixx="0.03" ixy="0.0" ixz="0.0" iyy="0.03" iyz="0.0" izz="0.03"/>
    </inertial>
  </link>
  <joint name="joint_3" type="revolute">
    <axis xyz="1 0 0"/>
    <limit effort="1000.0" lower="-2.88" upper="2.88" velocity="0.5"/>
    <parent link="link2"/>
    <child link="link3"/>
    <origin xyz="0 0 0.41"/>
  </joint>
  <link name="link4">
    <visual>
      <geometry>
        <cylinder length="0.44" radius="0.0125"/>
      </geometry>
      <origin rpy="0 0 0" xyz="0 0 0.22"/>
      <material name="white"/>
    </visual>
    <collision>
      <geometry>
        <cylinder length="0.44" radius="0.0125"/>
      </geometry>
      <origin rpy="0 0 0" xyz="0 0 0.22"/>
    </collision>
    <inertial>
      <mass value="0.1"/>
      <inertia ixx="0.03" ixy="0.0" ixz="0.0" iyy="0.03" iyz="0.0" izz="0.03"/>
    </inertial>
  </link>
  <joint name="joint_4" type="revolute">
    <axis xyz="0 0 1"/>
    <limit effort="1000.0" lower="-6.4" upper="6.4" velocity="0.5"/>
    <parent link="link3"/>
    <child link="link4"/>
  </joint>
  <link name="link5">
    <visual>
      <geometry>
        <cylinder length="0.18" radius="0.02"/>
      </geometry>
      <origin rpy="0 0 0" xyz="0 0 0"/>
      <material name="white"/>
    </visual>
    <collision>
      <geometry>
        <cylinder length="0.18" radius="0.02"/>
      </geometry>
      <origin rpy="0 0 0" xyz="0 0 0"/>
    </collision>
    <inertial>
      <mass value="0.1"/>
      <inertia ixx="0.03" ixy="0.0" ixz="0.0" iyy="0.03" iyz="0.0" izz="0.03"/>
    </inertial>
  </link>
  <joint name="joint_5" type="revolute">
    <axis xyz="1 0 0"/>
    <!-- 100 stopni -->
    <limit effort="1000.0" lower="-1.75" upper="1.75" velocity="0.5"/>
    <parent link="link5"/>
    <child link="link5_ext"/>
    <origin rpy="0 0 0" xyz="0 0 0.09"/>
  </joint>
  <link name="link5_ext">
    <visual>
      <geometry>
        <cylinder length="0.001" radius="0.001"/>
      </geometry>
      <origin rpy="0 0 0" xyz="0 0 0"/>
      <material name="white"/>
    </visual>
    <collision>
      <geometry>
        <cylinder length="0.001" radius="0.001"/>
      </geometry>
      <origin rpy="0 0 0" xyz="0 0 0"/>
    </collision>
    <inertial>
      <mass value="0.1"/>
      <inertia ixx="0.03" ixy="0.0" ixz="0.0" iyy="0.03" iyz="0.0" izz="0.03"/>
    </inertial>
  </link>
  <link name="link6">
    <visual>
      <geometry>
        <cylinder length="0.001" radius="0.0445"/>
      </geometry>
      <origin rpy="0 0 0" xyz="0 0 -0.0"/>
      <material name="white"/>
    </visual>
    <collision>
      <geometry>
        <cylinder length="0.01" radius="0.0445"/>
      </geometry>
      <origin rpy="0 0 0" xyz="0 0 -0.0"/>
    </collision>
    <inertial>
      <mass value="0.1"/>
      <inertia ixx="0.03" ixy="0.0" ixz="0.0" iyy="0.03" iyz="0.0" izz="0.03"/>
    </inertial>
  </link>
  <link name="link6_ext">

    </link>
  <link name="ee">
    </link>
  <link name="link6_to_gripper">

    </link>
  <joint name="joint_5_fix" type="fixed">
    <parent link="link4"/>
    <child link="link5"/>
    <origin rpy="0 0 0" xyz="0 0 0.53"/>
  </joint>
  <joint name="joint_6_fix" type="fixed">
    <parent link="link6"/>
    <child link="link6_ext"/>
    <origin rpy="-1.57 -1.57 0" xyz="0 0 0"/>
  </joint>
  <joint name="joint_6" type="revolute">
    <axis xyz="0 0 1"/>
    <limit effort="1000.0" lower="-3.4032" upper="3.4032" velocity="0.75"/>
    <parent link="link5_ext"/>
    <child link="link6"/>
    <!-- <origin rpy="0 0 0" xyz="0.15 0.20 0.0"/> -->
    <origin rpy="0 0 0" xyz="-0.02 0.02 0.0"/>
  </joint>
  <joint name="joint_6_to_gripper" type="fixed">
    <parent link="link6_ext"/>
    <child link="link6_to_gripper"/>
    <origin rpy="1.57 0 0" xyz="0 0 0"/>
  </joint>
  <link name="gripper_fixed">
    <visual>
      <geometry>
        <mesh filename="package://kalman_arm_moveit_config/meshes/gripper/gripper_bottom.stl" scale="0.001 0.001 0.001"/>
      </geometry>
      <origin rpy="0 0 0" xyz="-0.04 -0.04 -0.12"/>
      <material name="white"/>
    </visual>
    <collision>
      <geometry>
        <mesh filename="package://kalman_arm_moveit_config/meshes/gripper/gripper_bottom.stl" scale="0.001 0.001 0.001"/>
      </geometry>
      <origin rpy="0 0 0" xyz="-0.04 -0.04 -0.12"/>
    </collision>
    <inertial>
      <mass value="0.1"/>
      <inertia ixx="0.03" ixy="0.0" ixz="0.0" iyy="0.03" iyz="0.0" izz="0.03"/>
    </inertial>
  </link>
  <joint name="gripper_fixed_joint" type="fixed">
    <parent link="link6_to_gripper"/>
    <child link="gripper_fixed"/>
    <origin rpy="0 4.71238898 0" xyz="0 0 0"/>
  </joint>
  <joint name="ee_fixed_joint" type="fixed">
    <parent link="link6_ext"/>
    <child link="ee"/>
    <origin rpy="0 0 0" xyz="0.2 0 0"/>
  </joint>
  <link name="gripper_moving">
    <visual>
      <geometry>
        <mesh filename="package://kalman_arm_moveit_config/meshes/gripper/gripper_top.stl" scale="0.001 0.001 0.001"/>
      </geometry>
      <material name="white"/>
      <origin rpy="0 0 0" xyz="-0.014 -0.12 -0.035"/>
    </visual>
    <collision>
      <geometry>
        <mesh filename="package://kalman_arm_moveit_config/meshes/gripper/gripper_top.stl" scale="0.001 0.001 0.001"/>
      </geometry>
      <origin rpy="0 0 0" xyz="-0.014 -0.12 -0.035"/>
    </collision>
    <inertial>
      <mass value="0.1"/>
      <inertia ixx="0.03" ixy="0.0" ixz="0.0" iyy="0.03" iyz="0.0" izz="0.03"/>
    </inertial>
  </link>
  <joint name="gripper_moving_joint" type="revolute">
    <parent link="link6_to_gripper"/>
    <child link="gripper_moving"/>
    <axis xyz="0 0 1"/>
    <limit effort="1000.0" lower="-0.1" upper="1.57" velocity="0.5"/>
    <origin rpy="0 0 1.57079633" xyz="0.0 0.014 0"/>
  </joint>
  <joint name="fix" type="fixed">
    <parent link="flange"/>
    <child link="arm_link"/>
    <origin rpy="0 0 0"/>
  </joint>
  <transmission name="trans_joint_1">
    <type>transmission_interface/SimpleTransmission</type>
    <joint name="joint_1">
      <hardwareInterface>hardware_interface/PositionJointInterface</hardwareInterface>
    </joint>
    <actuator name="joint_1_motor">
      <hardwareInterface>hardware_interface/PositionJointInterface</hardwareInterface>
      <mechanicalReduction>1</mechanicalReduction>
    </actuator>
  </transmission>
  <transmission name="trans_joint_2">
    <type>transmission_interface/SimpleTransmission</type>
    <joint name="joint_2">
      <hardwareInterface>hardware_interface/PositionJointInterface</hardwareInterface>
    </joint>
    <actuator name="joint_2_motor">
      <hardwareInterface>hardware_interface/PositionJointInterface</hardwareInterface>
      <mechanicalReduction>1</mechanicalReduction>
    </actuator>
  </transmission>
  <transmission name="trans_joint_3">
    <type>transmission_interface/SimpleTransmission</type>
    <joint name="joint_3">
      <hardwareInterface>hardware_interface/PositionJointInterface</hardwareInterface>
    </joint>
    <actuator name="joint_3_motor">
      <hardwareInterface>hardware_interface/PositionJointInterface</hardwareInterface>
      <mechanicalReduction>1</mechanicalReduction>
    </actuator>
  </transmission>
  <transmission name="trans_joint_4">
    <type>transmission_interface/SimpleTransmission</type>
    <joint name="joint_4">
      <hardwareInterface>hardware_interface/PositionJointInterface</hardwareInterface>
    </joint>
    <actuator name="joint_4_motor">
      <hardwareInterface>hardware_interface/PositionJointInterface</hardwareInterface>
      <mechanicalReduction>1</mechanicalReduction>
    </actuator>
  </transmission>
  <transmission name="trans_joint_5">
    <type>transmission_interface/SimpleTransmission</type>
    <joint name="joint_5">
      <hardwareInterface>hardware_interface/PositionJointInterface</hardwareInterface>
    </joint>
    <actuator name="joint_5_motor">
      <hardwareInterface>hardware_interface/PositionJointInterface</hardwareInterface>
      <mechanicalReduction>1</mechanicalReduction>
    </actuator>
  </transmission>
  <transmission name="trans_joint_6">
    <type>transmission_interface/SimpleTransmission</type>
    <joint name="joint_6">
      <hardwareInterface>hardware_interface/PositionJointInterface</hardwareInterface>
    </joint>
    <actuator name="joint_6_motor">
      <hardwareInterface>hardware_interface/PositionJointInterface</hardwareInterface>
      <mechanicalReduction>1</mechanicalReduction>
    </actuator>
  </transmission>
  <transmission name="trans_gripper">
    <type>transmission_interface/SimpleTransmission</type>
    <joint name="gripper_moving_joint">
      <hardwareInterface>hardware_interface/PositionJointInterface</hardwareInterface>
    </joint>
    <actuator name="gripper_motor">
      <hardwareInterface>hardware_interface/PositionJointInterface</hardwareInterface>
      <mechanicalReduction>1</mechanicalReduction>
    </actuator>
  </transmission>
  <gazebo>
    <plugin filename="libgazebo_ros_control.so" name="gazebo_ros_control">
      <robotNamespace>/</robotNamespace>
    </plugin>
  </gazebo>
  <!-- <xacro:include filename="$(find kalman_arm_moveit_config)/urdf/gripper.urdf.xacro" /> -->
  <ros2_control name="kalman_arm" type="system">
    <hardware>
      <plugin>kalman_arm_controller/ArmSystem</plugin>
    </hardware>
    <joint name="joint_1">
      <command_interface name="position">
        <param name="min">{-2*pi}</param>
        <param name="max">{2*pi}</param>
      </command_interface>
      <command_interface name="velocity">
        <param name="min">-3.15</param>
        <param name="max">3.15</param>
      </command_interface>
      <state_interface name="position">
        <param name="initial_value">0.0</param>
      </state_interface>
      <state_interface name="velocity"/>
    </joint>
    <joint name="joint_2">
      <command_interface name="position">
        <param name="min">{-2*pi}</param>
        <param name="max">{2*pi}</param>
      </command_interface>
      <command_interface name="velocity">
        <param name="min">-3.15</param>
        <param name="max">3.15</param>
      </command_interface>
      <state_interface name="position">
        <param name="initial_value">0.0</param>
      </state_interface>
      <state_interface name="velocity"/>
    </joint>
    <joint name="joint_3">
      <command_interface name="position">
        <param name="min">{-pi}</param>
        <param name="max">{pi}</param>
      </command_interface>
      <command_interface name="velocity">
        <param name="min">-3.15</param>
        <param name="max">3.15</param>
      </command_interface>
      <state_interface name="position">
        <param name="initial_value">0.0</param>
      </state_interface>
      <state_interface name="velocity"/>
    </joint>
    <joint name="joint_4">
      <command_interface name="position">
        <param name="min">{-2*pi}</param>
        <param name="max">{2*pi}</param>
      </command_interface>
      <command_interface name="velocity">
        <param name="min">-3.2</param>
        <param name="max">3.2</param>
      </command_interface>
      <state_interface name="position">
        <param name="initial_value">0.0</param>
      </state_interface>
      <state_interface name="velocity"/>
    </joint>
    <joint name="joint_5">
      <command_interface name="position">
        <param name="min">{-2*pi}</param>
        <param name="max">{2*pi}</param>
      </command_interface>
      <command_interface name="velocity">
        <param name="min">-3.2</param>
        <param name="max">3.2</param>
      </command_interface>
      <state_interface name="position">
        <param name="initial_value">0.0</param>
      </state_interface>
      <state_interface name="velocity"/>
    </joint>
    <joint name="joint_6">
      <command_interface name="position">
        <param name="min">{-2*pi}</param>
        <param name="max">{2*pi}</param>
      </command_interface>
      <command_interface name="velocity">
        <param name="min">-3.2</param>
        <param name="max">3.2</param>
      </command_interface>
      <state_interface name="position">
        <param name="initial_value">0.0</param>
      </state_interface>
      <state_interface name="velocity"/>
    </joint>
    <joint name="gripper_moving_joint">
      <command_interface name="position">
        <param name="min">{-2*pi}</param>
        <param name="max">{2*pi}</param>
      </command_interface>
      <command_interface name="velocity">
        <param name="min">-3.2</param>
        <param name="max">3.2</param>
      </command_interface>
      <state_interface name="position">
        <param name="initial_value">0.0</param>
      </state_interface>
      <state_interface name="velocity"/>
    </joint>
    <!-- <sensor name="tcp_fts_sensor">
        <state_interface name="force.x"/>
        <state_interface name="force.y"/>
        <state_interface name="force.z"/>
        <state_interface name="torque.x"/>
        <state_interface name="torque.y"/>
        <state_interface name="torque.z"/>
      </sensor> -->
  </ros2_control>
</robot>
