<?xml version="1.0"?>
<robot xmlns:xacro="http://www.ros.org/wiki/xacro" name="gripper">
    
    
    <link name="gripper_fixed">
        <visual>
            <geometry>
                <box size="0.15 0.05 0.05" />
            </geometry>
            <material name="white" />
        </visual>
        <collision>
            <geometry>
                <box size="0.15 0.05 0.05" />
            </geometry>
        </collision>        
    </link>

    <joint name="gripper_fixed_joint" type="fixed">
        <parent link="link6_ext"/>
        <child link="gripper_fixed"/>
        <origin rpy="0 0 0" xyz="0 0 -0.06" />

    </joint>

    <link name="gripper_moving">
            <visual>
            <geometry>
                <box size="0.15 0.05 0.05" />
            </geometry>
            <material name="white" />
        </visual>
        <collision>
            <geometry>
                <box size="0.15 0.0 0.05" />
            </geometry>
        </collision>        
    </link>
    
    <joint name="gripper_moving_joint" type="revolute">
        <parent link="link6_ext"/>
        <child link="gripper_moving"/>
        <axis xyz="0 0 1" />
        <limit effort="1000.0" lower="0" upper="1.57" velocity="0.5" />
        <origin rpy="0 0 0" xyz="0 0 0.06" />
    </joint>


</robot>